Workbook

Sheet valores
B1: Tapetes cadeira | E1: custo em dolar
A2: AGOCTANCORE | B2: 5600413207451 | C2: Alpha Gamer Octan Core Gaming Chair Mat | D2: 100x100x3MM | E2: 9.8
A3: AGKADRANCORE | B3: 5600413207444 | C3: Alpha Gamer Kadran Core Gaming Chair Mat | D3: 140x60x75cm ?? | E3: 9.8
B4: Mesas | E4: custo em dolar
A5: AGRAYAV2 | B5: 5600413205556 | C5: Alpha Gamer Raya V2 - Gaming Table | D5: 100x60x75cm | E5: 34.4
A6: AGKIRAV3 | B6: 5600413205563 | C6: Alpha Gamer Kira V3 - Gaming Table | D6: 140x60x75cm | E6: 40.9
A7: AGZORYARGBBK | B7: 5600413207307 | C7: Alpha Gamer Zorya RGB Black - Secretaria Gaming Altura Regulável | D7: 140x71x75-120cm | E7: 107
A8: AGZORYARGBWT | B8: 5600413207314 | C8: Alpha Gamer Zorya RGB White - Secretaria Gaming Altura Regulável | D8: 140x71x75-120cm | E8: 108.5
A9: AGZORYAPRORGBBK | B9: 5600413208151 | C9: Alpha Gamer Zorya Pro RGB Black - Secretaria Gaming Altura Regulável | D9: 160x71x75-120cm | E9: 124.6
A10: AGZORYAPRORGBWT | B10: 5600413208168 | C10: Alpha Gamer Zorya Pro RGB White - Secretaria Gaming Altura Regulável | D10: 160x71x75-120cm | E10: 126.6
A11: AGSTARLARGBWT | B11: 5600413207352 | C11: Alpha Gamer Starla RGB White - Secretária Gaming | D11: 140x71x75cm | E11: 71.5
A12: AGSTARLARGBBK | B12: 5600413207345 | C12: Alpha Gamer Starla RGB Black - Secretária Gaming | D12: 140x71x75cm | E12: 73
A13: AGGEMINARGBBK | B13: 5600413207321 | C13: Alpha Gamer Gemina RGB Black - Secretária Gaming | D13: 140x60x75cm | E13: 38
A14: AGGEMINABK | B14: 5600413207338 | C14: Alpha Gamer Gemina Black - Secretária Gaming | D14: 140x60x75cm | E14: 27
C15: Acessorios | D15: OBS | E15: custo em dolar
A16: AGFBCLEANER | B16: 5600413207178 | C16: Alpha Gamer Fabric Cleaner | E16: 3.63
A17: AGPULTHRCLEANER | B17: 5600413207185 | C17: Alpha Gamer Leather Cleaner | E17: 3.63
A18: AGNAVIRGB | B18: 5600413206218 | C18: Alpha Gamer Navi Heavy-Duty Single Monitor RGB | E18: 34.01
A19: AGNAVIDRGB | B19: 5600413206225 | C19: Alpha Gamer Navi Heavy-Duty Dual Monitor RGB | E19: 57.5
A20: AGBPBK | B20: 5600413208069 | C20: Alpha Gamer Backpack Black | E20: 12.28
A21: AGBPGRY | B21: 5600413208076 | C21: Alpha Gamer Backpack Grey | E21: 12.28
C22: Cadeiras | D22: OBS | E22: custo em dolar
A23: AGSWELLBK | B23: 5600413207963 | C23: Alpha Gamer Swell Black - UE RC-1171E (Flow 360) | E23: 143
A24: AGSWELLGRY | B24: 5600413207970 | C24: Alpha Gamer Swell Grey - UE RC-1171E (Flow 360) | E24: 150
A25: AGSWELLWTGRY | B25: 5600413207987 | C25: Alpha Gamer Swell White / Grey - UE RC-1171E (Flow 360) | E25: 150
A26: AGTIDEBK | B26: 5600413207826 | C26: Alpha Gamer Tide Black- UE RC-1161E | E26: 162
A27: AGTIDEGRY | B27: 5600413207833 | C27: Alpha Gamer Tide Grey - UE RC-1161E | E27: 169
A28: AGMISTBK | B28: 5600413207802 | C28: Alpha Gamer Mist - UE RC-1109E | E28: 136
A29: AGMISTBKGRY | B29: 5600413207819 | C29: Alpha Gamer Mist Black / Grey - UE RC-1109E | E29: 136
A30: AGWAVEBK | B30: 5600413207789 | C30: Alpha Gamer Wave Black | UE MC-1152E | E30: 109
A31: AGWAVEBKGRY | B31: 5600413207796 | C31: Alpha Gamer Wave Black / Grey | UE MC-1152E | E31: 109
A32: AGLUNAV2 | B32: 5600413207390 | C32: Alpha Gamer Luna V2 - Cadeira em Malha | D32: 5 | E32: 71
A33: AGLUNAGRY | B33: 5600413207758 | C33: Alpha Gamer Luna Grey - Cadeira em Malha | E33: 80.5
A34: AGIRIS | B34: 5600413206362 | C34: Alpha Gamer Iris - Cadeira em Malha | E34: 88
A35: AGAURORA | B35: 5600413206355 | C35: Alpha Gamer Aurora - Cadeira em Malha | E35: 98
A36: AGASTRID | B36: 5600413206416 | C36: Alpha Gamer Astrid - Cadeira em Malha | E36: 145
A37: AGSTELLA-BK | B37: 5600413206423 | C37: Alpha Gamer Stella Black - Cadeira em Malha | E37: 60.5
A38: AGSTELLA-GRY | B38: 5600413206430 | C38: Alpha Gamer Stella Grey - Cadeira em Malha | E38: 65.5
A39: AGSTELLA-WT-GRY | B39: 5600413206447 | C39: Alpha Gamer Stella White / Grey - Cadeira em Malha | E39: 65.5
C40: Cadeiras | D40: OBS | E40: custo em dolar
...

Sheet RESUMO
G5: INICIO
B6: REFERENCIA | C6: PRODUTOS | D6: QUANT.
B7: OFFYPIXIEMINIPT | C7: Offy Pixie Mini Wireless / Bluetooth Keyboard PT | D7: 1000
B8: OFFYPIXIEPT | C8: Offy Pixie Wireless / Bluetooth Keyboard PT | D8: 1000
B9: OFFYFLEXIMINIPT | C9: Offy Flexi Mini Wireless / Bluetooth Keyboard PT | D9: 1000
B10: OFFYFLEXIPT | C10: Offy Flexi Wireless / Bluetooth Keyboard PT | D10: 1000
B11: OFFYFLEXIMIDPT | C11: Offy Flexi Mid Wireless / Bluetooth Keyboard PT | D11: 1000
B12: OFFYPIXIETABPT | C12: Offy Pixie Tab Wireless / Bluetooth Keyboard PT | D12: 1000
B13: OFFYNEXO | C13: Offy Nexo Wireless / Bluetooth Ergonomic Mouse 4800 DPI | D13: 1500
B14: OFFYVEXI | C14: Offy Vexi Wireless / Bluetooth Ergonomic Vertical Mouse 4800 DPI | D14: 1000
B15: OFFYLEXI | C15: Offy Lexi Wireless / Bluetooth Mouse 4800 DPI | D15: 1000
B16: OFFYAXIO | C16: Offy Axio Wireless / Bluetooth Ergonomic Mouse 4800 DPI | D16: 1000
B17: OFFYNEXOWT | C17: Offy Nexo Wireless / Bluetooth Ergonomic Mouse 4800 DPI - White | D17: 1000
B18: OFFYOPTIXPRO | C18: Offy Optix Pro 4K UHD 2160P Webcam | D18: 500
... B20: NXCBAYMX2 | C20: Nox Coolbay MX2 | D20: 120
B23: REFERENCIA | C23: PRODUTOS | D23: QUANT.
B24: AGGEMINABK | C24: Alpha Gamer Gemina Black - Secretária Gaming | D24: 180
B25: AGGEMINARGBBK | C25: Alpha Gamer Gemina RGB Black - Secretária Gaming | D25: 50
B26: AGZORYARGBBK | C26: Alpha Gamer Zorya RGB Black - Secretaria Gaming Altura Regulável | D26: 150
B27: AGZORYAPRORGBBK | C27: Alpha Gamer Zorya Pro RGB Black - Secretaria Gaming Altura Regulável | D27: 161
B28: AGZORYAPRORGBWT | C28: Alpha Gamer Zorya Pro RGB White - Secretaria Gaming Altura Regulável | D28: 100
B32: REFERENCIA | C32: PRODUTOS | D32: QUANT.
B33: OFFYLYCABK | C33: =IFERROR(IF(B33<>"",VLOOKUP(B33,'[1]Conversão Artigos'!$C:$D,2,FALSE),""),"") -> Offy Lyca Black - Cadeira de escritório em malha | D33: 16
B34: OFFYPRISMABK | C34: =IFERROR(IF(B34<>"",VLOOKUP(B34,'[1]Conversão Artigos'!$C:$D,2,FALSE),""),"") -> Offy Prisma Ergonomic Office Chair Black | D34: 120
B35: OFFYPRISMAWTPK | C35: =IFERROR(IF(B35<>"",VLOOKUP(B35,'[1]Conversão Artigos'!$C:$D,2,FALSE),""),"") -> Offy Prisma Ergonomic Office Chair White / Pink | D35: 30
B36: OFFYPRISMAWTTQ | C36: =IFERROR(IF(B36<>"",VLOOKUP(B36,'[1]Conversão Artigos'!$C:$D,2,FALSE),""),"") -> Offy Prisma Ergonomic Office Chair White / Turquoise | D36: 50
B37: OFFYPRISMAWTGRY | C37: =IFERROR(IF(B37<>"",VLOOKUP(B37,'[1]Conversão Artigos'!$C:$D,2,FALSE),""),"") -> Offy Prisma Ergonomic Office Chair White / Grey | D37: 100
B38: OFFYPRISMAWTBG | C38: =IFERROR(IF(B38<>"",VLOOKUP(B38,'[1]Conversão Artigos'!$C:$D,2,FALSE),""),"") -> Offy Prisma Ergonomic Office Chair White / Beige | D38: 60
B39: OFFYLYMA | C39: =IFERROR(IF(B39<>"",VLOOKUP(B39,'[1]Conversão Artigos'!$C:$D,2,FALSE),""),"") -> Offy Lyma - Cadeira de escritório em malha | D39: 50
B40: OFFYLYCABKBK | C40: PCDIGA | D40: 20
B41: AGTIDEBK | C41: Alpha Gamer Tide Black PCDIGA EDITION | D41: 50
B42: AGNAVIDRGB | C42: Alpha Gamer Navi Heavy-Duty Dual Monitor RGB | D42: 200
B46: REFERENCIA | C46: PRODUTOS | D46: QUANT.
B47: AGALEGRAEVOBLDF | C47: Alpha Gamer Alegra Evo - Blue Dusk Fabric | D47: 40
B48: AGALEGRAEVOSBKF | C48: Alpha Gamer Alegra Evo - Shadow Black Fabric | D48: 120
B49: AGALEGRAEVOGRYSF | C49: Alpha Gamer Alegra Evo - Grey Storm Fabric | D49: 80
B50: AGALEGRAEVOMBKPU | C50: Alpha Gamer Alegra Evo - Midnight Black PU | D50: 25
B51: AGALEGRAEVOTGRYPU | C51: Alpha Gamer Alegra Evo - Titanium Grey PU | D51: 25
B52: AGALEGRAEVOSGRYF | C52: Alpha Gamer Alegra Evo - Smoke Grey Fabric | D52: 25

Sheet Fornecedores_Contentores
A1: VALOR | B1: Companhia | C1: Fornecedor | D1: CONTENTOR | E1: TIPO | F1: SELO | G1: SAIDA - ETD | H1: CHEGADA POD - ETA | I1: Ready | K1: OBS | L1: Data entrega cliente | M1: POD | N1: DESTINO FINAL | O1: P.O's | P1: OBS | Q1: Mercadoria
A2: 3823.3 | B2: MSC | C2: HUZHOU JIERU HOME | D2: CAAU5904294 | E2: 40HC | F2: FX42416620 | G2: 45970 | H2: 46012 | I2: SIM | L2: 46030 | M2: Riachos | N2: PC Diga | O2: JR1055-60 | Q2: Cadeiras Mesh
A3: 3823.3 | B3: MSC | C3: HUZHOU JIERU HOME | D3: TCNU2374129 | E3: 40HC | F3: FX42237675 | G3: 45966 | H3: 46018 | I3: SIM | L3: 46029 | M3: Riachos | N3: PC Diga | O3: JR1055-59 | Q3: Cadeiras Mesh
A4: 3485.05 | B4: MSC | C4: ANJI DINCHEN | D4: MSMU4227658 | E4: 40HC | F4: FX43262251 | G4: 45970 | H4: 46012 | I4: SIM | L4: 46028 | M4: Bobadela | N4: WORTEN | O4: PTAG11-602 | Q4: Cadeiras
A5: 3910.3 | B5: MSC | C5: HUZHOU JIERU HOME | D5: MSMU5852428 | E5: 40HC | F5: FX43774142 | G5: 45979 | H5: 46017 | I5: SIM | L5: 46036 | M5: Riachos | N5: PC Diga | O5: JR1055-61 | Q5: Cadeiras Mesh
A6: 8616 | B6: Maersk | C6: HUZHOU JIERU HOME | D6: CAAU7083644 | E6: 40HC | F6: CN9908775 | G6: 45978 | H6: 46023 | I6: SIM | L6: 46037 | M6: Riachos | N6: FJMPC | O6: JR1055-62 | Q6: Cadeiras Mesh
B7: Maersk | C7: HUZHOU JIERU HOME | D7: MRKU4170138 | E7: 40HC | F7: CN9908483 | G7: 45978 | H7: 46023 | I7: SIM | L7: 46038 | M7: Riachos | N7: FJMPC | O7: JR1055-62 | Q7: Cadeiras Mesh
B8: Maersk | C8: HUZHOU JIERU HOME | D8: MRKU4976524 | E8: 40HC | F8: CN9908670 | G8: 45978 | H8: 46023 | I8: SIM | L8: 46041 | M8: Riachos | N8: FJMPC | O8: JR1055-62 | Q8: Cadeiras Mesh
A9: 3206 | B9: Maersk | C9: ANJI DINCHEN | D9: MRKU3244447 | E9: 40 HC | F9: CN2479404 | G9: 45978 | H9: 46023 | I9: SIM | L9: 46037 | M9: RIACHOS | N9: PC DIGA | O9: PTAG11-619 | Q9: Cadeiras
A10: 3823.3 | B10: MSC | C10: HUZHOU JIERU HOME | D10: TCNU1554912 | E10: 40HC | F10: FX42237633 | G10: 45966 | H10: 46022 | I10: SIM | L10: 46038 | M10: Riachos | N10: PC Diga | O10: JR1055-58 | Q10: Cadeiras Mesh
A11: 2954 | B11: Maersk | C11: HUZHOU JIERU HOME | D11: MSKU0654460 | E11: 40HC | F11: CN2520604 | G11: 45978 | H11: 46023 | I11: SIM | L11: 46044 | M11: Bobadela | N11: Worten | O11: JR1055-50 | Q11: Cadeiras Mesh
A12: 2866.75 | B12: MSC | C12: UE FURNITURE CO., LTD | D12: FSCU8840228 | E12: 40HC | F12: FX43773837 | G12: 45966 | H12: 46022 | I12: SIM | L12: 46042 | M12: RIACHOS | N12: PC DIGA | O12: FJMPC-2504 | P12: CADEIRAS MESH NOVAS | Q12: Cadeiras Mesh
A13: 3727.25 | B13: Maersk | C13: GUANGZHOU AOJIE | D13: MRKU3567877 | E13: 40HC | F13: CN3242583 | G13: 45992 | H13: 45666 | I13: SIM | L13: 46045 | M13: LISBOA | N13: FJMPC | O13: 25SM10062 | P13: Tapetes Pc Diga | Q13: Caixas
A14: 3727.25 | B14: Maersk | C14: ANJI HAIWEI SMART FURNITURE | D14: MRKU4372041 | E14: 40HC | F14: CN4676253 | G14: 45999 | H14: 46041 | I14: SIM | L14: 46050 | M14: LISBOA | N14: FJMPC | O14: HW137-2406-1 | Q14: Mesas
A15: 3389 | B15: Maersk | C15: ANJI DINCHEN | D15: MSKU9770693 | E15: 40HC | F15: CN4551737 | G15: 45992 | H15: 46041 | I15: SIM | L15: 46051 | M15: LISBOA | N15: Worten | O15: PTAG11-636 | Q15: Cadeiras
A16: 3389 | B16: Maersk | C16: ANJI DINCHEN | D16: CAIU8294053 | E16: 40HC | F16: CN4619129 | G16: 45992 | H16: 46041 | I16: SIM | L16: 46051 | M16: LISBOA | N16: Worten | O16: PTAG11-296 | Q16: Cadeiras
A17: 3902.55 | B17: CMACGM | C17: SUAVE TECHNOLOGY | D17: TCNU5152906 | E17: 40HC | F17: M7961357 | G17: 45994 | H17: 15/02/2026 ?? | I17: SIM | K17: 30/01 Tanger | L17: 46052 | M17: LISBOA | N17: FJMPC | O17: ST2509017 | P17: Caixas Coolers Zolid | Q17: Caixas
A18: 3679 | B18: Hapag Lloyd | C18: SUAVE TECHNOLOGY / Atlas | D18: FANU3359264 | E18: 40HC | F18: HLK1038932 | G18: 45994 | H18: 46057 | I18: SIM | L18: 46064 | M18: LISBOA | N18: FJMPC | O18: 25SM10062 | P18: Caixas Atlas | Q18: Caixas
A19: 3745 | B19: Maersk | C19: HUZHOU JIERU HOME | D19: HASU4497484 | E19: 40HC | F19: CN4510533 | G19: 46006 | H19: 46060 | I19: SIM | L19: 46072 | M19: LISBOA | N19: FJMPC | O19: JR1055-63 | Q19: Cadeiras Mesh
A20: 3645 | B20: Maersk | C20: HUZHOU JIERU HOME | D20: TRHU4437683 | E20: 40HC | F20: CN4510551 | G20: 46006 | H20: 46060 | I20: SIM | L20: 46073 | M20: LISBOA | N20: FJMPC | O20: JR1055-63 | Q20: Cadeiras Mesh
A21: 3745 | B21: Maersk | C21: DONGLAI SMART HOME TECH LTD | D21: MRSU7266658 | E21: 40HC | F21: CN4510540 | G21: 46006 | H21: 46060 | I21: SIM | L21: 46071 | M21: LISBOA | N21: Worten | O21: PTAG11-604 | Q21: Cadeiras
A22: 3517 | B22: CMACGM | C22: HUZHOU JIERU HOME | D22: SEKU7815267 | E22: 40HC | F22: M6801403 | G22: 45993 | H22: 46067 | I22: SIM | L22: 46076 | M22: LISBOA | N22: FJMPC | O22: JR1055-63&64B | Q22: Cadeiras Mesh
A23: 3517 | B23: CMACGM | C23: DONGLAI SMART HOME TECH LTD | D23: SEKU7814189 | E23: 40HC | F23: M6801357 | G23: 45993 | H23: 46067 | I23: SIM | L23: 46076 | M23: LISBOA | N23: RP / FJMPC | O23: PTAG11-638 | P23: RODAS | Q23: Cadeiras
A24: 3517 | B24: CMACGM | C24: DONGLAI SMART HOME TECH LTD | D24: SEKU7815225 | E24: 40HC | F24: M6801351 | G24: 45993 | H24: 46067 | I24: SIM | L24: 46077 | M24: LISBOA | N24: Worten / Bobadela | O24: PTAG11-641 | Q24: Cadeiras
A25: 3517 | B25: CMACGM | C25: HUZHOU JIERU HOME | D25: SEKU7815204 | E25: 40HC | F25: M6801292 | G25: 45993 | H25: 46067 | I25: SIM | L25: 46076 | M25: LISBOA | N25: MEO / FJMPC | O25: JR1055-65 | Q25: Cadeiras Mesh
A26: 3517 | B26: CMACGM | C26: HUZHOU JIERU HOME | D26: SEKU7815288 | E26: 40HC | F26: M6801417 | G26: 45993 | H26: 46067 | I26: SIM | L26: 46078 | M26: LISBOA | N26: FJMPC | O26: JR1055-63&64B | Q26: Cadeiras Mesh
A27: 3517 | B27: CMACGM | C27: DONGLAI SMART HOME TECH LTD | D27: CMAU7126778 | E27: 40HC | F27: M4174103 | G27: 45993 | H27: 46067 | I27: SIM | L27: 46078 | M27: LISBOA | N27: Worten / Bobadela | O27: PTAG11-639 | Q27: Cadeiras
A28: 4465 | B28: CMACGM | C28: DONGLAI SMART HOME TECH LTD | D28: SEKU7816495 | E28: 40HC | F28: M8120280 | G28: 46040 | H28: 46093 | I28: SIM | L28: 46097 | M28: LISBOA | N28: RP / FJMPC | O28: PTAG11-629 | Q28: Cadeiras
A29: 4378 | B29: MSC | C29: HUZHOU JIERU HOME | D29: MSMU6056997 | E29: 40HC | F29: FX45118318 | G29: 46054 | H29: 46088 | I29: SIM | L29: 46099 | M29: RIACHOS | N29: FJMPC / Nuno | O29: JR1055-69
A30: 4465 | B30: CMACGM | C30: HUZHOU JIERU HOME | D30: SEKU7816514 | E30: 40HC | F30: M8113937 | G30: 46040 | H30: 46093 | I30: SIM | L30: 46099 | M30: LISBOA | N30: WOrten / Bobadela | O30: JR1055-66 | Q30: Cadeiras Mesh
A31: 4465 | B31: CMACGM | C31: HUZHOU JIERU HOME | D31: SEKU7816577 | E31: 40HC | F31: M8113760 | G31: 46040 | H31: 46093 | I31: SIM | L31: 46099 | M31: LISBOA | N31: WOrten / Bobadela | O31: JR1055-67 | Q31: Cadeiras Mesh
A32: 4465 | B32: CMACGM | C32: HUZHOU JIERU HOME | D32: SEKU7816480 | E32: 40HC | F32: M8113990 | G32: 46040 | H32: 46093 | I32: SIM | L32: 46100 | M32: LISBOA | N32: Radio Popular / FJMPC | O32: JR1055-68 | Q32: Cadeiras Mesh
A33: 4465 | B33: CMACGM | C33: DONGLAI SMART HOME TECH LTD | D33: SEKU7816788 | E33: 40HC | F33: M8113984 | G33: 46040 | H33: 46093 | I33: SIM | L33: 46101 | M33: LISBOA | N33: Worten / Bobadela | O33: PTAG11-603 | Q33: Cadeiras
A34: 4465 | B34: CMACGM | C34: DONGLAI SMART HOME TECH LTD | D34: SEKU7816767 | E34: 40HC | F34: M8113936 | G34: 46040 | H34: 46093 | I34: SIM | L34: 46098 | M34: LISBOA | N34: meo / FJMPC | O34: PTAG11-637 | Q34: Cadeiras
A35: 4210 | B35: ONE | C35: SUAVETECH | D35: NYKU4794090 | E35: 40HC | F35: CNDT06184 | G35: 46038 | H35: 46110 | I35: SIM | L35: 46119 | M35: LISBOA | N35: FJMPC | O35: ST2511002 +ST2509017 | P35: NOVIDADES | Q35: Caixas Coolers Zolid / Mochilas / Combo Offy
A36: 4210 | B36: ONE | C36: GUANGZHOU AOJIE | D36: ONEU1147585 | E36: 40HC | F36: CNDT06033 | G36: 46039 | H36: 46115 | I36: SIM | L36: 46125 | M36: LISBOA | N36: FJMPC | O36: 25SM04050 -1 | P36: Caixas / Fontes NOX | Q36: Caixas / Fontes NOX
A37: 4000 | B37: Maersk | C37: DONGLAI SMART HOME TECH LTD | D37: MRSU3054645 | E37: 40HC | F37: CN4606494 | G37: 46057 | H37: 46121 | I37: SIM | L37: 46128 | M37: LISBOA | N37: FJMPC | O37: PTAG11-635 | Q37: Cadeiras
A38: 4232 | B38: CMACGM | C38: DONGLAI SMART HOME TECH LTD | D38: CMAU7035404 | E38: 40HC | F38: M6794095 | G38: 46052 | H38: 46115 | I38: SIM | L38: 46132 | M38: LISBOA | N38: FJMPC / FNAC | O38: PTAG11-632 | Q38: Cadeiras
A39: 4000 | B39: Maersk | C39: DONGLAI SMART HOME TECH LTD | D39: MRSU7112185 | E39: 40 HC | F39: CN4649997 | G39: 46057 | H39: 46121 | I39: SIM | L39: 46129 | M39: LISBOA | N39: FJMPC | O39: PTAG11-625 | Q39: Cadeiras
A40: 4322 | B40: CMACGM | C40: DONGLAI SMART HOME TECH LTD | D40: CMAU6742059 | E40: 40HC | F40: M6793376 | G40: 46048 | H40: 46122 | I40: SIM | L40: 46133 | M40: LISBOA | N40: Worten / Bobadela | O40: PTAG11-640 | Q40: Cadeiras
...

Sheet ONEU6060805
C2: REFERENCIA | E2: PRODUTOS | F2: QUANT. | J2: INICIO
C3: AGAURORA | D3: 5600413206355 | E3: Alpha Gamer Aurora - Cadeira em Malha | F3: 200 | G3: =IF(C3<>"",VLOOKUP(C3,valores!A:E,5,FALSE),IF(D3<>"",VLOOKUP(D3,valores!B:E,4,FALSE),"")) -> 98 | H3: =G3/$E$14 -> #DIV/0!
C4: AGSTELLA-WT-GRY | D4: 5600413206447 | E4: Alpha Gamer Stella White / Grey - Cadeira em Malha | F4: 180 | G4: =IF(C4<>"",VLOOKUP(C4,valores!A:E,5,FALSE),IF(D4<>"",VLOOKUP(D4,valores!B:E,4,FALSE),"")) -> 65.5 | H4: =G4/$E$14 -> #DIV/0!
G5: =IF(C5<>"",VLOOKUP(C5,valores!A:E,5,FALSE),IF(D5<>"",VLOOKUP(D5,valores!B:E,4,FALSE),"")) | H5: =G5/$E$14 -> #VALUE!
G6: =IF(C6<>"",VLOOKUP(C6,valores!A:E,5,FALSE),IF(D6<>"",VLOOKUP(D6,valores!B:E,4,FALSE),"")) | H6: =G6/$E$14 -> #VALUE!
G7: =IF(C7<>"",VLOOKUP(C7,valores!A:E,5,FALSE),IF(D7<>"",VLOOKUP(D7,valores!B:E,4,FALSE),"")) | H7: =G7/$E$14 -> #VALUE!
G8: =IF(C8<>"",VLOOKUP(C8,valores!A:E,5,FALSE),IF(D8<>"",VLOOKUP(D8,valores!B:E,4,FALSE),"")) | H8: =G8/$E$14 -> #VALUE!
G9: =IF(C9<>"",VLOOKUP(C9,valores!A:E,5,FALSE),IF(D9<>"",VLOOKUP(D9,valores!B:E,4,FALSE),"")) | H9: =G9/$E$14 -> #VALUE!
G10: =IF(C10<>"",VLOOKUP(C10,valores!A:E,5,FALSE),IF(D10<>"",VLOOKUP(D10,valores!B:E,4,FALSE),"")) | H10: =G10/$E$14 -> #VALUE!
G11: =IF(C11<>"",VLOOKUP(C11,valores!A:E,5,FALSE),IF(D11<>"",VLOOKUP(D11,valores!B:E,4,FALSE),"")) | H11: =G11/$E$14 -> #VALUE!
G12: =IF(C12<>"",VLOOKUP(C12,valores!A:E,5,FALSE),IF(D12<>"",VLOOKUP(D12,valores!B:E,4,FALSE),"")) | H12: =G12/$E$14 -> #VALUE!
D14: Cambio

Sheet TCNU5901856
C2: REFERENCIA | E2: PRODUTOS | F2: QUANT. | J2: INICIO
B3: NOVIDADE | C3: AGALEGRAEVOBLDF | D3: 5600413207673 | E3: Alpha Gamer Alegra Evo - Blue Dusk Fabric | F3: 40 | G3: =IF(C3<>"",VLOOKUP(C3,valores!A:E,5,FALSE),IF(D3<>"",VLOOKUP(D3,valores!B:E,4,FALSE),"")) -> 133.5 | H3: =G3/$E$14 -> #DIV/0!
B4: NOVIDADE | C4: AGALEGRAEVOSBKF | D4: 5600413207703 | E4: Alpha Gamer Alegra Evo - Shadow Black Fabric | F4: 115 | G4: =IF(C4<>"",VLOOKUP(C4,valores!A:E,5,FALSE),IF(D4<>"",VLOOKUP(D4,valores!B:E,4,FALSE),"")) -> 133.5 | H4: =G4/$E$14 -> #DIV/0!
B5: NOVIDADE | C5: AGALEGRAEVOGRYSF | D5: 5600413207710 | E5: Alpha Gamer Alegra Evo - Grey Storm Fabric | F5: 80 | G5: =IF(C5<>"",VLOOKUP(C5,valores!A:E,5,FALSE),IF(D5<>"",VLOOKUP(D5,valores!B:E,4,FALSE),"")) -> 133.5 | H5: =G5/$E$14 -> #DIV/0!
C6: AGALEGRAEVOMBKPU | D6: 5600413207635 | E6: Alpha Gamer Alegra Evo - Midnight Black PU | F6: 25 | G6: =IF(C6<>"",VLOOKUP(C6,valores!A:E,5,FALSE),IF(D6<>"",VLOOKUP(D6,valores!B:E,4,FALSE),"")) -> 133.5 | H6: =G6/$E$14 -> #DIV/0!
C7: AGALEGRAEVOTGRYPU | D7: 5600413207659 | E7: Alpha Gamer Alegra Evo - Titanium Grey PU | F7: 25 | G7: =IF(C7<>"",VLOOKUP(C7,valores!A:E,5,FALSE),IF(D7<>"",VLOOKUP(D7,valores!B:E,4,FALSE),"")) -> 133.5 | H7: =G7/$E$14 -> #DIV/0!
C8: AGALEGRAEVOSGRYF | D8: 5600413207666 | E8: Alpha Gamer Alegra Evo - Smoke Grey Fabric | F8: 25 | G8: =IF(C8<>"",VLOOKUP(C8,valores!A:E,5,FALSE),IF(D8<>"",VLOOKUP(D8,valores!B:E,4,FALSE),"")) -> 133.5 | H8: =G8/$E$14 -> #DIV/0!
G9: =IF(C9<>"",VLOOKUP(C9,valores!A:E,5,FALSE),IF(D9<>"",VLOOKUP(D9,valores!B:E,4,FALSE),"")) | H9: =G9/$E$14 -> #VALUE!
G10: =IF(C10<>"",VLOOKUP(C10,valores!A:E,5,FALSE),IF(D10<>"",VLOOKUP(D10,valores!B:E,4,FALSE),"")) | H10: =G10/$E$14 -> #VALUE!
G11: =IF(C11<>"",VLOOKUP(C11,valores!A:E,5,FALSE),IF(D11<>"",VLOOKUP(D11,valores!B:E,4,FALSE),"")) | H11: =G11/$E$14 -> #VALUE!
G12: =IF(C12<>"",VLOOKUP(C12,valores!A:E,5,FALSE),IF(D12<>"",VLOOKUP(D12,valores!B:E,4,FALSE),"")) | H12: =G12/$E$14 -> #VALUE!
D14: Cambio

Sheet ONEU1030860
C2: REFERENCIA | E2: PRODUTOS | F2: QUANT. | J2: INICIO
C3: OFFYLYCABK | D3: 5600413206386 | E3: Offy Lyca Black - Cadeira de escritório em malha | F3: 16 | G3: 58 | H3: =G3/$E$14 -> #DIV/0!
B4: NOVIDADE | C4: OFFYPRISMABK | D4: 5600413208540 | E4: Offy Prisma Ergonomic Office Chair Black | F4: 120 | G4: 28.5 | H4: =G4/$E$14 -> #DIV/0!
B5: NOVIDADE | C5: OFFYPRISMAWTPK | D5: 5600413208557 | E5: Offy Prisma Ergonomic Office Chair White / Pink | F5: 30 | G5: 31.5 | H5: =G5/$E$14 -> #DIV/0!
B6: NOVIDADE | C6: OFFYPRISMAWTTQ | D6: 5600413208564 | E6: Offy Prisma Ergonomic Office Chair White / Turquoise | F6: 50 | G6: 31.5 | H6: =G6/$E$14 -> #DIV/0!
B7: NOVIDADE | C7: OFFYPRISMAWTGRY | D7: 5600413208571 | E7: Offy Prisma Ergonomic Office Chair White / Grey | F7: 100 | G7: 31.5 | H7: =G7/$E$14 -> #DIV/0!
B8: NOVIDADE | C8: OFFYPRISMAWTBG | D8: 5600413208588 | E8: Offy Prisma Ergonomic Office Chair White / Beige | F8: 60 | G8: 31.5 | H8: =G8/$E$14 -> #DIV/0!
C9: OFFYLYMA | D9: 5600413206324 | E9: Offy Lyma - Cadeira de escritório em malha | F9: 50 | G9: 34.5 | H9: =G9/$E$14 -> #DIV/0!
C10: OFFYLYCABKBK | E10: PCDIGA | F10: 20 | G10: 58 | H10: =G10/$E$14 -> #DIV/0!
C11: AGTIDEBK | D11: 5600413207826 | E11: Alpha Gamer Tide Black PCDIGA EDITION | F11: 50 | G11: 155 | H11: =G11/$E$14 -> #DIV/0!
C12: AGNAVIDRGB | D12: 5600413206225 | E12: Alpha Gamer Navi Heavy-Duty Dual Monitor RGB | F12: 200 | G12: 57.5 | H12: =G12/$E$14 -> #DIV/0!
D14: Cambio

Sheet TRHU4608301
C2: REFERENCIA | E2: PRODUTOS | F2: QUANT. | J2: INICIO
C3: OFFYLYCAWT | D3: 5600413206409 | E3: Offy Lyca White - Cadeira de escritório em malha | F3: 50 | G3: 63 | H3: =G3/$E$9 -> #DIV/0!
C4: OFFYLYMA | D4: 5600413206324 | E4: Offy Lyma - Cadeira de escritório em malha | F4: 148 | G4: 34.5 | H4: =G4/$E$9 -> #DIV/0!
C5: OFFYLYMAGREY | D5: 5600413207741 | E5: Offy Lyma Grey | F5: 100 | G5: 37.5 | H5: =G5/$E$9 -> #DIV/0!
C6: AGAURORA | D6: 5600413206355 | E6: Alpha Gamer Aurora - Cadeira em malha | F6: 140 | G6: 98 | H6: =G6/$E$9 -> #DIV/0!
H7: =G7/$E$9 -> #DIV/0!
D9: Cambio

Sheet NYKU0846132
C2: REFERENCIA | E2: PRODUTOS | F2: QUANT. | J2: INICIO
C3: AGGEMINABK | D3: 5600413207338 | E3: Alpha Gamer Gemina Black - Secretária Gaming | F3: 180 | G3: 27 | H3: =G3/$E$9 -> #DIV/0!
C4: AGGEMINARGBBK | D4: 5600413207321 | E4: Alpha Gamer Gemina RGB Black - Secretária Gaming | F4: 50 | G4: 38 | H4: =G4/$E$9 -> #DIV/0!
C5: AGZORYARGBBK | D5: 5600413207307 | E5: Alpha Gamer Zorya RGB Black - Secretaria Gaming Altura Regulável | F5: 150 | G5: 107 | H5: =G5/$E$9 -> #DIV/0!
C6: AGZORYAPRORGBBK | D6: 5600413208151 | E6: Alpha Gamer Zorya Pro RGB Black - Secretaria Gaming Altura Regulável | F6: 161 | G6: 124.6 | H6: =G6/$E$9 -> #DIV/0!
C7: AGZORYAPRORGBWT | D7: 5600413208168 | E7: Alpha Gamer Zorya Pro RGB White - Secretaria Gaming Altura Regulável | F7: 100 | G7: 126.6 | H7: =G7/$E$9 -> #DIV/0!
D9: Cambio

Sheet FCIU3873512
C2: REFERENCIA | E2: PRODUTOS | F2: QUANT. | J2: INICIO
C3: OFFYPIXIEMINIPT | D3: 5600413207499 | E3: Offy Pixie Mini Wireless / Bluetooth Keyboard PT | F3: 1000 | G3: 9.4 | H3: =G3/$E$18 -> #DIV/0!
C4: OFFYPIXIEPT | D4: 5600413207482 | E4: Offy Pixie Wireless / Bluetooth Keyboard PT | F4: 1000 | G4: 11.9 | H4: =G4/$E$18 -> #DIV/0!
C5: OFFYFLEXIMINIPT | D5: 5600413207475 | E5: Offy Flexi Mini Wireless / Bluetooth Keyboard PT | F5: 1000 | G5: 10.4 | H5: =G5/$E$18 -> #DIV/0!
C6: OFFYFLEXIPT | D6: 5600413207468 | E6: Offy Flexi Wireless / Bluetooth Keyboard PT | F6: 1000 | G6: 12.6 | H6: =G6/$E$18 -> #DIV/0!
B7: NOVIDADE | C7: OFFYFLEXIMIDPT | D7: 5600413208182 | E7: Offy Flexi Mid Wireless / Bluetooth Keyboard PT | F7: 1000 | G7: 11.9 | H7: =G7/$E$18 -> #DIV/0!
B8: NOVIDADE | C8: OFFYPIXIETABPT | D8: 5600413208175 | E8: Offy Pixie Tab Wireless / Bluetooth Keyboard PT | F8: 1000 | G8: 12.8 | H8: =G8/$E$18 -> #DIV/0!
C9: OFFYNEXO | D9: 5600413207413 | E9: Offy Nexo Wireless / Bluetooth Ergonomic Mouse 4800 DPI | F9: 1500 | G9: 12.4 | H9: =G9/$E$18 -> #DIV/0!
C10: OFFYVEXI | D10: 5600413207420 | E10: Offy Vexi Wireless / Bluetooth Ergonomic Vertical Mouse 4800 DPI | F10: 1000 | G10: 12.7 | H10: =G10/$E$18 -> #DIV/0!
B11: NOVIDADE | C11: OFFYLEXI | D11: 5600413208281 | E11: Offy Lexi Wireless / Bluetooth Mouse 4800 DPI | F11: 1000 | G11: 8.2 | H11: =G11/$E$18 -> #DIV/0!
B12: NOVIDADE | C12: OFFYAXIO | D12: 5600413208274 | E12: Offy Axio Wireless / Bluetooth Ergonomic Mouse 4800 DPI | F12: 1000 | G12: 8.6 | H12: =G12/$E$18 -> #DIV/0!
B13: NOVIDADE | C13: OFFYNEXOWT | D13: 5600413208472 | E13: Offy Nexo Wireless / Bluetooth Ergonomic Mouse 4800 DPI - White | F13: 1000 | G13: 12.7 | H13: =G13/$E$18 -> #DIV/0!
B14: NOVIDADE | C14: OFFYOPTIXPRO | D14: 5600413208496 | E14: Offy Optix Pro 4K UHD 2160P Webcam | F14: 500 | G14: 12.5 | H14: =G14/$E$18 -> #DIV/0!
B15: NOVIDADE | C15: OFFYOPTIX | D15: 5600413208489 | E15: Offy Optix FHD 1080P Webcam | F15: 1000 | G15: 8.3 | H15: =G15/$E$18 -> #DIV/0!
C16: NXCBAYMX2 | D16: 8436532165603 | E16: Nox Coolbay MX2 | F16: 120 | G16: 12.46 | H16: =G16/$E$18 -> #DIV/0!
D18: Cambio

Sheet SEGU5176476
C2: REFERENCIA | E2: PRODUTOS | F2: QUANT. | J2: INICIO
C3: AGGAIA-DK-GREY-WT-V2 | D3: 5600413207727 | E3: Alpha Gamer Gaia - Dark Grey / White V2 | F3: 260 | G3: 69.01 | H3: =G3/$E$9 -> #DIV/0!
C4: AGTERION-FB-GRY | D4: 5600413204504 | E4: Alpha Gamer Terion - Fabric Grey | F4: 60 | G4: 92.26 | H4: =G4/$E$9 -> #DIV/0!
H5: =G5/$E$9 -> #DIV/0!
H6: =G6/$E$9 -> #DIV/0!
D9: Cambio

Sheet KKFU7935971
C2: REFERENCIA | E2: PRODUTOS | F2: QUANT. | J2: INICIO
C3: AGNEBULAOE-PU-BWN | D3: 5600413206379 | E3: Alpha Gamer Nebula Office Edition - PU Brown | F3: 70 | G3: 84.42 | H3: =G3/$E$9 -> #DIV/0!
C4: AGCYGNUS | D4: 5600413204191 | E4: Alpha Gamer Cygnus RGB | F4: 310 | G4: 71.64 | H4: =G4/$E$9 -> #DIV/0!
H5: =G5/$E$9 -> #DIV/0!
H6: =G6/$E$9 -> #DIV/0!
D9: Cambio

Sheet CMAU7447870
C2: REFERENCIA | E2: PRODUTOS | F2: QUANT. | J2: INICIO
C3: AGGAIA-DK-GREY-WT-V2 | D3: 5600413207727 | E3: Alpha Gamer Gaia - Dark Grey / White V2 | F3: 80 | G3: 69.01 | H3: =G3/$E$9 -> 59.286942
C4: AGGAIA-LT-GREY-V2 | D4: 5600413207109 | E4: Alpha Gamer Gaia - Light Grey V2 | F4: 90 | G4: 69.01 | H4: =G4/$E$9 -> 59.286942
C5: AGTERION-FB-GRY | D5: 5600413204504 | E5: Alpha Gamer Terion - Fabric Grey | F5: 100 | G5: 92.26 | H5: =G5/$E$9 -> 79.261168
H6: =G6/$E$9 -> 0
D9: Cambio | E9: 1.164

Sheet TCNU3632887
C2: REFERENCIA | E2: PRODUTOS | F2: QUANT. | J2: INICIO
C3: AGNEBULAOE-PU-BWN | D3: 5600413206379 | E3: Alpha Gamer Nebula Office Edition - PU Brown | F3: 308 | G3: 84.42 | H3: =G3/$E$9 -> 72.525773
C4: AGNEBULA-GRY-BL | D4: 5600413205006 | E4: Alpha Gamer Nebula master Grey/Blue | F4: 24 | G4: 84.42 | H4: =G4/$E$9 -> 72.525773
C5: AGNEBULA-GRY-PK | D5: 5600413205013 | E5: Alpha Gamer Nebula master Grey/Pink | F5: 10 | G5: 84.42 | H5: =G5/$E$9 -> 72.525773
C6: AGNEBULA-GRY-O | D6: 5600413205020 | E6: Alpha Gamer Nebula master Grey/Orange | F6: 15 | G6: 84.42 | H6: =G6/$E$9 -> 72.525773
D9: Cambio | E9: 1.164

Sheet TLLU4428396
C2: REFERENCIA | E2: PRODUTOS | F2: QUANT. | J2: INICIO
C3: AGGAIA-LT-GREY-V2 | D3: 5600413207109 | E3: Alpha Gamer Gaia - Light Grey V2 | F3: 295 | G3: 69.01 | H3: =G3/$E$11 -> 59.286942
C4: AGNYSA-BK | D4: 5600413205488 | E4: Alpha Gamer Nysa - Black | F4: 95 | G4: 67.39 | H4: =G4/$E$11 -> 57.895189
H5: =G5/$E$11 -> 0
H6: =G6/$E$11 -> 0
H7: =G7/$E$11 -> 0
H8: =G8/$E$11 -> 0
D11: Cambio | E11: 1.164

Sheet TCNU3717752
C2: REFERENCIA | E2: PRODUTOS | F2: QUANT. | J2: INICIO
C3: AGCYRA-F-GREY | D3: 5600413205747 | E3: Alpha Gamer Cyra - Fabric Grey / Black | F3: 415 | G3: 43.12 | H3: =G3/$E$11 -> 37.044674
H4: =G4/$E$11 -> 0
H5: =G5/$E$11 -> 0
H6: =G6/$E$11 -> 0
H7: =G7/$E$11 -> 0
H8: =G8/$E$11 -> 0
D11: Cambio | E11: 1.164

Sheet DDDU5046665
C2: REFERENCIA | E2: PRODUTOS | F2: QUANT. | J2: INICIO
C3: AGNEBULA | D3: 5600413204054 | E3: Alpha Gamer Nebula master Grey/Black | F3: 357 | G3: 84.42 | H3: =G3/$E$11 -> 72.525773
H4: =G4/$E$11 -> 0
H5: =G5/$E$11 -> 0
H6: =G6/$E$11 -> 0
H7: =G7/$E$11 -> 0
H8: =G8/$E$11 -> 0
D11: Cambio | E11: 1.164

Sheet TCLU8910094
C2: REFERENCIA | E2: PRODUTOS | F2: QUANT. | J2: INICIO
C3: AGSWELLBK | D3: 5600413207963 | E3: Alpha Gamer Swell Black | F3: 50 | G3: 143 | H3: =G3/$E$11 -> 122.85223
C4: AGSWELLGRY | D4: 5600413207970 | E4: Alpha Gamer Swell Grey | F4: 50 | G4: 150 | H4: =G4/$E$11 -> 128.86598
C5: AGSWELLWTGRY | D5: 5600413207987 | E5: Alpha Gamer Swell White / Grey | F5: 50 | G5: 150 | H5: =G5/$E$11 -> 128.86598
C6: AGTIDEBK | D6: 5600413207826 | E6: Alpha Gamer Tide Black | F6: 50 | G6: 162 | H6: =G6/$E$11 -> 139.17526
C7: AGTIDEGRY | D7: 5600413207833 | E7: Alpha Gamer Tide Grey | F7: 50 | G7: 169 | H7: =G7/$E$11 -> 145.189
H8: =G8/$E$11 -> 0
D11: Cambio | E11: 1.164

Sheet MSMU8426391
C2: REFERENCIA | E2: PRODUTOS | F2: QUANT. | J2: INICIO
C3: AGGALAXA-F-GRY-BK | D3: 5600413207154 | E3: Alpha Gamer Galaxa - Fabric Grey / Black | F3: 103 | G3: 86 | H3: =G3/$E$11 -> 73.123034
C4: AGGALAXA-PUL-BK | D4: 5600413207161 | E4: Alpha Gamer Galaxa - PU Black | F4: 110 | G4: 86 | H4: =G4/$E$11 -> 73.123034
C5: AGPTGC26 | D5: 5600413208298 | E5: Alpha Gamer Portugal 26 | F5: 150 | G5: 98.5 | H5: =G5/$E$11 -> 83.751382
H6: =G6/$E$11 -> 0
H7: =G7/$E$11 -> 0
H8: =G8/$E$11 -> 0
D11: Cambio | E11: 1.1761

Sheet TCLU6374264
C2: REFERENCIA | E2: PRODUTOS | F2: QUANT. | J2: INICIO
C3: AGLUNAV2 | D3: 5600413207390 | E3: Alpha Gamer Luna V2 - Cadeira em Malha | F3: 75 | G3: 71 | H3: =G3/$E$11 -> 60.996564
C4: AGAURORA | D4: 5600413206355 | E4: Alpha Gamer Aurora - Cadeira em Malha | F4: 130 | G4: 98 | H4: =G4/$E$11 -> 84.19244
C5: AGSTELLA-GRY | D5: 5600413206430 | E5: Alpha Gamer Stella Grey - Cadeira em Malha | F5: 80 | G5: 65.5 | H5: =G5/$E$11 -> 56.271478
C6: AGSTELLA-WT-GRY | D6: 5600413206447 | E6: Alpha Gamer Stella White / Grey - Cadeira em Malha | F6: 115 | G6: 65.5 | H6: =G6/$E$11 -> 56.271478
H7: =G7/$E$11 -> 0
H8: =G8/$E$11 -> 0
D11: Cambio | E11: 1.164

Sheet UETU5559061
C2: REFERENCIA | E2: PRODUTOS | F2: QUANT. | J2: INICIO
C3: AGAURORA | D3: 5600413206355 | E3: Alpha Gamer Aurora - Cadeira em malha | F3: 200 | G3: 98 | H3: =G3/$E$11 -> 84.163518
C4: AGIRIS | D4: 5600413206362 | E4: Alpha Gamer Iris - Cadeira em malha | F4: 80 | G4: 88 | H4: =G4/$E$11 -> 75.575404
C5: OFFYLYCAWT | D5: 5600413206409 | E5: Offy Lyca White - Cadeira de escritório em malha | F5: 29 | G5: 63 | H5: =G5/$E$11 -> 54.105119
C6: OFFYLYMAGREY | D6: 5600413207741 | E6: Offy Lyma Grey | F6: 60 | G6: 37.5 | H6: =G6/$E$11 -> 32.205428
H7: =G7/$E$11 -> 0
H8: =G8/$E$11 -> 0
D11: Cambio | E11: 1.1644

Sheet CAIU9472020
C2: REFERENCIA | E2: PRODUTOS | F2: QUANT. | J2: INICIO
C3: AGSTELLA-BK | D3: 5600413206423 | E3: Alpha Gamer Stella Black - Cadeira em malha | F3: 185 | G3: 60.5 | H3: =G3/$E$11 -> 51.95809
C4: AGSTELLA-GRY | D4: 5600413206430 | E4: Alpha Gamer Stella Grey - Cadeira em malha | F4: 100 | G4: 65.5 | H4: =G4/$E$11 -> 56.252147
C5: AGSTELLA-WT-GRY | D5: 5600413206447 | E5: Alpha Gamer Stella White / Grey - Cadeira em malha | F5: 120 | G5: 65.5 | H5: =G5/$E$11 -> 56.252147
C6: OFFYLYCAWT | D6: 5600413206409 | E6: Offy Lyca White - Cadeira de escritório em malha | F6: 38 | G6: 63 | H6: =G6/$E$11 -> 54.105119
H7: =G7/$E$11 -> 0
H8: =G8/$E$11 -> 0
D11: Cambio | E11: 1.1644

Sheet CMAU6149465
C2: REFERENCIA | E2: PRODUTOS | F2: QUANT. | J2: INICIO
C3: NXINFTYBETA | D3: 8436587974892 | E3: Nox Infinity Beta Airflow ATX Chassis | F3: 150 | G3: 12.83 | H3: =G3/$E$14 -> 11.01855
C4: NXHUMMERVSNBK | D4: 8436587974625 | E4: Nox Hummer Vision Black Mid Tower USB 3.0 | F4: 100 | G4: 15.81 | H4: =G4/$E$14 -> 13.577808
C5: NXHUMMERGLOCKWH | D5: 8436587974854 | E5: Nox Hummer Glock Frameless Glass Mid Tower White | F5: 80 | G5: 51.9 | H5: =G5/$E$14 -> 44.572312
C6: NXHUMMERGLOCKBK | D6: 8436587974847 | E6: Nox Hummer Glock Frameless Glass Mid Tower Black | F6: 100 | G6: 48.76 | H6: =G6/$E$14 -> 41.875644
C7: NXINFTYEPSILON | D7: 8436587974205 | E7: Nox Infinity Epsilon RGB M-ATX Chassis | F7: 100 | G7: 18.24 | H7: =G7/$E$14 -> 15.66472
C8: NXHUMMERVOID | D8: 8436587970399 | E8: Nox Hummer Void ATX Silent Case | F8: 233 | G8: 23.62 | H8: =G8/$E$14 -> 20.285125
C9: NXCBAYMX2 | D9: 8436532165603 | E9: Nox Coolbay MX2 | F9: 200 | G9: 12.46 | H9: =G9/$E$14 -> 10.70079
C10: 1IFEKBBASEKITPT | D10: 5600413203736 | E10: 1Life kb:base kit | F10: 2000 | G10: 2.65 | H10: =G10/$E$14 -> 2.2758502
C11: 1IFETECUFBTPTBK | D11: 5600413206768 | E11: 1Life teclado ultrafino Bluetooth PT BK | F11: 1000 | G11: 3.28 | H11: =G11/$E$14 -> 2.8169014
D14: Cambio | E14: 1.1644

Sheet TCNU7813630
C2: REFERENCIA | E2: PRODUTOS | F2: QUANT. | J2: INICIO
C3: AGGEMINARGBBK | D3: 5600413207321 | E3: Alpha Gamer Gemina RGB Black - Secretária Gaming | F3: 225 | G3: 38 | H3: =G3/$E$11 -> 32.690984
C4: AGGEMINABK | D4: 5600413207338 | E4: Alpha Gamer Gemina Black - Secretária Gaming | F4: 225 | G4: 27 | H4: =G4/$E$11 -> 23.227805
C5: AGSTARLARGBBK | D5: 5600413207345 | E5: Alpha Gamer Starla RGB Black - Secretária gaming | F5: 284 | G5: 71.5 | H5: =G5/$E$11 -> 61.510668
C6: AGZORYARGBBK | D6: 5600413207307 | E6: Alpha Gamer Zorya RGB Black - Secretaria Gaming Altura Regulável | F6: 124 | G6: 107 | H6: =G6/$E$11 -> 92.050929
H7: =G7/$E$11 -> 0
H8: =G8/$E$11 -> 0
H9: =G9/$E$11 -> 0
D11: Cambio | E11: 1.1624

Sheet MSMU6056997
C2: REFERENCIA | E2: PRODUTOS | F2: QUANT. | J2: INICIO
C3: AGSTELLA-GRY | D3: 5600413206430 | E3: Alpha Gamer Stella Grey - Cadeira em malha | F3: 50 | G3: 65.5 | H3: =G3/$E$10 -> 55.042017
C4: AGSTELLA-WT-GRY | D4: 5600413206447 | E4: Alpha Gamer Stella White / Grey - Cadeira em malha | F4: 50 | G4: 65.5 | H4: =G4/$E$10 -> 55.042017
C5: AGAURORA | D5: 5600413206355 | E5: Alpha Gamer Aurora - Cadeira em malha | F5: 200 | G5: 98 | H5: =G5/$E$10 -> 82.352941
C6: AGSTELLA-BK | D6: 5600413206423 | E6: Alpha Gamer Stella Black - Cadeira em malha | F6: 80 | G6: 60.5 | H6: =G6/$E$10 -> 50.840336
H7: =G7/$E$10 -> 0
H8: =G8/$E$10 -> 0
D10: Cambio | E10: 1.19

Sheet MRSU3054645
C2: REFERENCIA | E2: PRODUTOS | F2: QUANT. | J2: INICIO
C3: AGGAIA-DK-GREY-BLUE-V2 | D3: 5600413207130 | E3: Alpha Gamer Gaia - Dark Grey / Blue V2 | F3: 30 | G3: 69.01 | H3: =G3/$E$16 -> 58.927504
C4: AGGAIA-DK-GREY-V2 | D4: 5600413207093 | E4: Alpha Gamer Gaia-Dark Grey V2 | F4: 30 | G4: 69.01 | H4: =G4/$E$16 -> 58.927504
C5: AGATENA-BK | D5: 5600413205303 | E5: Alpha Gamer Atena- Black | F5: 40 | G5: 66.51 | H5: =G5/$E$16 -> 56.792759
C6: AGATENA-BK-RED | D6: 5600413205310 | E6: Alpha Gamer Atena-Black/Red | F6: 45 | G6: 66.51 | H6: =G6/$E$16 -> 56.792759
C7: AGGALAXA-F-GRY-BK | D7: 5600413207154 | E7: Alpha Gamer Galaxa-Fabric Grey/Black | F7: 40 | G7: 88 | H7: =G7/$E$16 -> 75.143028
C8: AGGALAXA-PUL-BK | D8: 5600413207161 | E8: Alpha Gamer Galaxa -pu Black | F8: 30 | G8: 88 | H8: =G8/$E$16 -> 75.143028
C9: AGNYSA-BK | D9: 5600413205488 | E9: Alpha Gamer Nysa - Black | F9: 20 | G9: 67.39 | H9: =G9/$E$16 -> 57.544189
C10: AGZETA-BK | D10: 5600413203804 | E10: Alpha Gamer Zeta Black | F10: 40 | G10: 58.9 | H10: =G10/$E$16 -> 50.294595
C11: AGZETA-WHT-BK | D11: 5600413205761 | E11: Alpha Gamer Zeta -white/ Black | F11: 20 | G11: 58.9 | H11: =G11/$E$16 -> 50.294595
C12: AGGAIA-DK-GREY-OR-V2 | D12: 5600413207116 | E12: Alpha Gamer Gaia -Dark Grey/Orange V2 | F12: 10 | G12: 69.01 | H12: =G12/$E$16 -> 58.927504
C13: AGGAIA-DK-GREY-WT-V2 | D13: 5600413207727 | E13: Alpha Gamer Gaia -Dark Grey/ white V2 | F13: 50 | G13: 69.01 | H13: =G13/$E$16 -> 58.927504
C14: AGGAIA-LT-GREY-WT-V2 | D14: 5600413207734 | E14: Alpha Gamer Gaia -Light Grey/ white V2 | F14: 50 | G14: 69.01 | H14: =G14/$E$16 -> 58.927504
D16: Cambio | E16: 1.1711

Sheet CMAU6742059
C2: REFERENCIA | E2: PRODUTOS | F2: QUANT. | J2: INICIO
C3: AGCYRA-F-GREY | D3: 5600413205747 | E3: Alpha Gamer Cyra - Fabric Grey / Black | F3: 239 | G3: 43.12 | H3: =G3/$E$11 -> 36.820084
C4: AGGAIA-LT-GREY-V2 | D4: 5600413207109 | E4: Alpha Gamer Gaia - Light Grey V2 | F4: 99 | G4: 69.01 | H4: =G4/$E$11 -> 58.927504
C5: AGGAIA-DK-GREY-WT-V2 | D5: 5600413207727 | E5: Alpha Gamer Gaia - Dark Grey / White V2 | F5: 50 | G5: 69.01 | H5: =G5/$E$11 -> 58.927504
H6: =G6/$E$11 -> 0
H7: =G7/$E$11 -> 0
H8: =G8/$E$11 -> 0
H9: =G9/$E$11 -> 0
D11: Cambio | E11: 1.1711

Sheet SEKU7815204
C2: REFERENCIA | E2: PRODUTOS | F2: QUANT. | J2: INICIO
C3: AGSTELLA-BK | D3: 5600413206423 | E3: Alpha Gamer Stella Black-Cadeira em malha | F3: 230 | G3: 60.5 | H3: =G3/$E$11 -> 50.716741
C4: AGSTELLA-GRY | D4: 5600413206430 | E4: Alpha Gamer Stella Grey-Cadeira em malha | F4: 100 | G4: 65.5 | H4: =G4/$E$11 -> 54.908207
C5: AGSTELLA-WT-GRY | D5: 5600413206447 | E5: Alpha Gamer Stella white /Grey-Cadeira em malha | F5: 80 | G5: 65.5 | H5: =G5/$E$11 -> 54.908207
C6: AGIRIS | D6: 5600413206362 | E6: Alpha Gamer lris-Cadeira em malha | F6: 10 | G6: 88 | H6: =G6/$E$11 -> 73.769805
C7: AGASTRID | D7: 5600413206416 | E7: Alpha Gamer Astrid-cadeira em malha | F7: 10 | G7: 145 | H7: =G7/$E$11 -> 121.55252
H8: =G8/$E$11 -> 0
H9: =G9/$E$11 -> 0
D11: Cambio | E11: 1.1929

Sheet SEKU7816495
C2: REFERENCIA | E2: PRODUTOS | F2: QUANT. | J2: INICIO
C3: AGGAIA-LT-GREY-WT-V2 | D3: 5600413207734 | E3: Alpha Gamer Gaia - Light Grey / White V2 | F3: 70 | G3: 69.01 | H3: =G3/$E$11 -> 58.45828
C4: AGMAYA-BK | D4: 5600413205372 | E4: Alpha Gamer Maya Black | F4: 190 | G4: 45.3 | H4: =G4/$E$11 -> 38.373571
C5: AGZETA-BK | D5: 5600413203804 | E5: Alpha Gamer Zeta Black | F5: 50 | G5: 58.9 | H5: =G5/$E$11 -> 49.894113
C6: AGALEGRA-F-GRY | D6: 5600413204955 | E6: Alpha Gamer Alegra Fabric Grey | F6: 30 | G6: 119.2 | H6: =G6/$E$11 -> 100.97416
C7: AGZETA-BK-R | D7: 5600413203811 | E7: Alpha Gamer Zeta Black/Red | F7: 30 | G7: 58.9 | H7: =G7/$E$11 -> 49.894113
H8: =G8/$E$11 -> 0
H9: =G9/$E$11 -> 0
D11: Cambio | E11: 1.1805

Sheet SEKU7816767
C2: REFERENCIA | E2: PRODUTOS | F2: QUANT. | J2: INICIO
C3: AGALEGRA-F-GRY-V2 | D3: 5600413207055 | E3: Alpha Gamer Alegra - Fabric Grey / Black V2 | F3: 20 | G3: 119.2 | H3: =G3/$E$11 -> 100.97416
C4: AGALEGRA-PUL-BK-V2 | D4: 5600413207062 | E4: Alpha Gamer Alegra - PU Leather Black V2 | F4: 20 | G4: 124.2 | H4: =G4/$E$11 -> 105.20966
C5: AGMAYA-BK | D5: 5600413205372 | E5: Alpha Gamer Maya Black | F5: 240 | G5: 45.3 | H5: =G5/$E$11 -> 38.373571
C6: AGMAYA-BK-RED | D6: 5600413205389 | E6: Alpha Gamer Maya Black /red | F6: 50 | G6: 45.3 | H6: =G6/$E$11 -> 38.373571
C7: AGMAYA-BK-BLUE | D7: 5600413205396 | E7: Alpha Gamer Maya Black / blue | F7: 40 | G7: 45.3 | H7: =G7/$E$11 -> 38.373571
H8: =G8/$E$11 -> 0
H9: =G9/$E$11 -> 0
D11: Cambio | E11: 1.1805

Sheet SEKU7816788
C2: REFERENCIA | E2: PRODUTOS | F2: QUANT. | J2: INICIO
C3: AGNEBULA | D3: 5600413204054 | E3: Alpha Gamer Nebula master Grey/Black | F3: 357 | G3: 84.42 | H3: =G3/$E$11 -> 71.512071
H4: =G4/$E$11 -> 0
H5: =G5/$E$11 -> 0
H6: =G6/$E$11 -> 0
H7: =G7/$E$11 -> 0
H8: =G8/$E$11 -> 0
H9: =G9/$E$11 -> 0
D11: Cambio | E11: 1.1805

Sheet ONEU1147585
C2: REFERENCIA | E2: PRODUTOS | F2: QUANT. | J2: INICIO
C3: NXCBAYRX | D3: 8436532163036 | E3: Nox Coolbay RX | F3: 100 | G3: 10.9 | H3: =G3/$E$13 -> 9.3925032
C4: NXCBAYMX2 | D4: 8436532165603 | E4: Nox Coolbay MX2 | F4: 100 | G4: 11.7 | H4: =G4/$E$13 -> 10.081861
C5: ZLDRADION | D5: 5600413206843 | E5: Zolyd Radion - ARGB ATX PC Case | F5: 100 | G5: 22.1 | H5: =G5/$E$13 -> 19.043516
C6: NXHUMMERFROST | D6: 8436587972638 | E6: Nox Hummer Frost ARGB Lighting Mid Tower | F6: 240 | G6: 12.67 | H6: =G6/$E$13 -> 10.917708
C7: NXURVX750BZ | D7: 8436532166969 | E7: Nox Urano VX 750W 80+ Bronze | F7: 1000 | G7: 37.3 | H7: =G7/$E$13 -> 32.141318
C8: NXURVX650BZ | D8: 8436532166952 | E8: Nox Urano VX 650W 80+ Bronze | F8: 1000 | G8: 30.4 | H8: =G8/$E$13 -> 26.195605
C9: NXURTX850BZ | D9: 8436532166976 | E9: Nox Urano TX 850W 80+ Bronze | F9: 500 | G9: 41.7 | H9: =G9/$E$13 -> 35.932788
C10: AGOCTANCORE | D10: 5600413207451 | E10: Alpha Gamer Octan Core Gaming Chair Mat | F10: 500 | G10: 9.8 | H10: =G10/$E$13 -> 8.4446359
C11: AGKADRANCORE | D11: 5600413207444 | E11: Alpha Gamer Kadran Core Gaming Chair Mat | F11: 500 | G11: 9.8 | H11: =G11/$E$13 -> 8.4446359
D13: Cambio | E13: 1.1605

Sheet NYKU4794090
C2: REFERENCIA | E2: PRODUTOS | F2: QUANT. | J2: INICIO
C3: 1IFEHDRAPID | D3: 5600413204146 | E3: 1Life hd:rapid 2.5 C to C SATA | F3: 500 | G3: 4.5 | H3: =G3/$E$44 -> 3.8119441
C4: 1IFEUSBC5IN1 | D4: 5600413203682 | E4: 1Life usb-c:5in1 HDMI / DEX / RJ45 | F4: 200 | G4: 8.5 | H4: =G4/$E$44 -> 7.2003388
C5: 1IFECRCITIZEN | D5: 5600413202777 | E5: 1Life cr:citizen | F5: 1000 | G5: 2.8 | H5: =G5/$E$44 -> 2.3718763
C6: 1IFECBUSBCLGTNG27W15M | D6: 5600413205952 | E6: 1Life cabo USB-C > Lightning 27W 1.5m | F6: 1000 | G6: 1.35 | H6: =G6/$E$44 -> 1.1435832
C7: 1IFECXEXT25USB3TRP | D7: 5600413205914 | E7: 1Life caixa externa HDD/SSD 2.5" USB 3.0 transp. | F7: 1000 | G7: 2.25 | H7: =G7/$E$44 -> 1.905972
C8: 1IFEHDFLUX3 | D8: 5600413203880 | E8: 1Life hd:flux 3 | F8: 500 | G8: 2.6 | H8: =G8/$E$44 -> 2.2024566
C9: 1IFENBCXENOGR | D9: 5600413205679 | E9: 1Life nbc: xeno laptop holder grey | F9: 500 | G9: 4.35 | H9: =G9/$E$44 -> 3.6848793
C10: 1IFENBCXENOBK | D10: 5600413205662 | E10: 1Life nbc: xeno laptop holder black | F10: 500 | G10: 4.35 | H10: =G10/$E$44 -> 3.6848793
C11: 1IFETCTA3ADAPT | D11: 5600413205587 | E11: 1Life usb: Type-C / Type-A 3.0 adapter 2pcs | F11: 500 | G11: 0.9 | H11: =G11/$E$44 -> 0.76238882
C12: 1IFETATC3ADAPT | D12: 5600413205570 | E12: 1Life usb: Type-A / Type-C 3.0 adapter 2pcs | F12: 500 | G12: 0.55 | H12: =G12/$E$44 -> 0.46590428
C13: AGBPBK | D13: 5600413208069 | E13: Alpha Gamer Backpack Black | F13: 500 | G13: 12.28 | H13: =G13/$E$44 -> 10.402372
C14: AGBPGRY | D14: 5600413208076 | E14: Alpha Gamer Backpack Grey | F14: 500 | G14: 12.28 | H14: =G14/$E$44 -> 10.402372
C15: OFFYSYNCROPT | D15: 5600413207505 | E15: Offy Syncro Wireless / Bluetooth Keyboard + Mouse PT | F15: 1000 | G15: 8.5 | H15: =G15/$E$44 -> 7.2003388
C16: ZLDNOVAARGB120PWMBK | D16: 5600413207529 | E16: Zolyd Nova ARGB 120 mm PWM Fan Black | F16: 250 | G16: 2.5 | H16: =G16/$E$44 -> 2.1177467
C17: ZLDNOVAARGB120PWMWT | D17: 5600413207536 | E17: Zolyd Nova ARGB 120 mm PWM Fan White | F17: 250 | G17: 2.65 | H17: =G17/$E$44 -> 2.2448115
C18: ZLDNOVAARGB120PWMNGBK | D18: 5600413208083 | E18: Zolyd Nova ARGB 120 mm PWM Negative Fan Black | F18: 250 | G18: 2.5 | H18: =G18/$E$44 -> 2.1177467
C19: ZLDNOVAARGB120PWMNGWT | D19: 5600413208090 | E19: Zolyd Nova ARGB 120 mm PWM Negative Fan White | F19: 250 | G19: 2.65 | H19: =G19/$E$44 -> 2.2448115
C20: ZLDFLUXARGBML120PWMKITBK | D20: 5600413207567 | E20: Zolyd Flux ARGB MagLink 120 mm PWM Fan Kit Black | F20: 250 | G20: 13 | H20: =G20/$E$44 -> 11.012283
C21: ZLDFLUXARGBML120PWMKITWT | D21: 5600413207574 | E21: Zolyd Flux ARGB MagLink 120 mm PWM Fan Kit White | F21: 250 | G21: 13.5 | H21: =G21/$E$44 -> 11.435832
C22: ZLDVERTAARGBEF120PWMKITBK | D22: 5600413207604 | E22: Zolyd Verta ARGB EasyFit 120 mm PWM Fan Kit Black | F22: 250 | G22: 11 | H22: =G22/$E$44 -> 9.3180856
C23: ZLDVERTAARGBEF120PWMKITWT | D23: 5600413207611 | E23: Zolyd Verta ARGB EasyFit 120 mm PWM Fan Kit White | F23: 250 | G23: 11.5 | H23: =G23/$E$44 -> 9.7416349
C24: ZLDB750 | D24: 5600413206928 | E24: Zolyd B750 - 750W 80 Plus Bronze ATX PSU | F24: 500 | G24: 37 | H24: =G24/$E$44 -> 31.342651
C25: ZLDNSKARIONBK | D25: 5600413208120 | E25: Zolyd Neo Series Karion Black Micro-ATX Computer Case | F25: 210 | G25: 23.5 | H25: =G25/$E$44 -> 19.906819
C26: ZLDNSKARIONWDBK | D26: 5600413208106 | E26: Zolyd Neo Series Karion WD Black Micro-ATX Computer Case | F26: 200 | G26: 27.7 | H26: =G26/$E$44 -> 23.464634
C27: ZLDNSKARIONWDWTBK | D27: 5600413208113 | E27: Zolyd Neo Series Karion WD White / Black Micro-ATX Computer Case | F27: 200 | G27: 29.2 | H27: =G27/$E$44 -> 24.735282
C28: ZLDPULSAR | D28: 5600413208045 | E28: Zolyd Pulsar - Caixa PC Micro-ATX | F28: 26 | G28: 26.9 | H28: =G28/$E$44 -> 22.786955
H29: =G29/$E$44 -> 0
H30: =G30/$E$44 -> 0
H31: =G31/$E$44 -> 0
H32: =G32/$E$44 -> 0
H33: =G33/$E$44 -> 0
H34: =G34/$E$44 -> 0
H35: =G35/$E$44 -> 0
H36: =G36/$E$44 -> 0
H37: =G37/$E$44 -> 0
H38: =G38/$E$44 -> 0
H39: =G39/$E$44 -> 0
H40: =G40/$E$44 -> 0
... H42: =G42/$E$44 -> 0
...

Sheet SEKU7816480
C2: REFERENCIA | E2: PRODUTOS | F2: QUANT. | J2: INICIO
C3: AGAURORA | D3: 5600413206355 | E3: Alpha Gamer Aurora - Cadeira em malha | F3: 340 | G3: 98 | H3: =G3/$E$11 -> 83.015671
H4: =G4/$E$11 -> 0
H5: =G5/$E$11 -> 0
H6: =G6/$E$11 -> 0
H7: =G7/$E$11 -> 0
H8: =G8/$E$11 -> 0
H9: =G9/$E$11 -> 0
D11: Cambio | E11: 1.1805

Sheet SEKU7816577
C2: REFERENCIA | E2: PRODUTOS | F2: QUANT. | J2: INICIO
C3: AGSTELLA-GRY | D3: 5600413206430 | E3: Alpha Gamer Stella Grey - Cadeira em malha | F3: 55 | G3: 65.5 | H3: =G3/$E$11 -> 55.484964
C4: AGSTELLA-WT-GRY | D4: 5600413206447 | E4: Alpha Gamer Stella White / Grey - Cadeira em malha | F4: 165 | G4: 65.5 | H4: =G4/$E$11 -> 55.484964
C5: AGAURORA | D5: 5600413206355 | E5: Alpha Gamer Aurora - Cadeira em malha | F5: 120 | G5: 98 | H5: =G5/$E$11 -> 83.015671
C6: AGSTELLA-BK | D6: 5600413206423 | E6: Alpha Gamer Stella Black - Cadeira em malha | F6: 60 | G6: 60.5 | H6: =G6/$E$11 -> 51.249471
H7: =G7/$E$11 -> 0
H8: =G8/$E$11 -> 0
H9: =G9/$E$11 -> 0
D11: Cambio | E11: 1.1805

Sheet SEKU7816514
C2: REFERENCIA | E2: PRODUTOS | F2: QUANT. | J2: INICIO
C3: AGAURORA | D3: 5600413206355 | E3: Alpha Gamer Aurora - Cadeira em malha | F3: 340 | G3: 98 | H3: =G3/$E$11 -> 83.015671
H4: =G4/$E$11 -> 0
H5: =G5/$E$11 -> 0
H6: =G6/$E$11 -> 0
H7: =G7/$E$11 -> 0
H8: =G8/$E$11 -> 0
H9: =G9/$E$11 -> 0
D11: Cambio | E11: 1.1805

Sheet SEKU7814189
C2: REFERENCIA | E2: PRODUTOS | F2: QUANT. | J2: INICIO
C3: AGGAIA-LT-GREY-WT-V2 | D3: 5600413207734 | E3: Alpha Gamer Gaia - Light Grey / White V2 | F3: 390 | G3: 69.01 | H3: =G3/$E$11 -> 57.850616
H4: =G4/$E$11 -> 0
D5: wheels | E5: MS-116 | F5: 50 | H5: =G5/$E$11 -> 0
D6: wheels | E6: MR-60P-16 | F6: 50 | H6: =G6/$E$11 -> 0
D7: wheels | E7: MR-65Y-05 | F7: 50 | H7: =G7/$E$11 -> 0
D8: wheels | E8: MR-60M-06 | F8: 50 | H8: =G8/$E$11 -> 0
H9: =G9/$E$11 -> 0
D11: Cambio | E11: 1.1929

Sheet SEKU7815225
C2: REFERENCIA | E2: PRODUTOS | F2: QUANT. | J2: INICIO
C3: AGNEBULA-GRY-PK | D3: 5600413205013 | E3: Alpha Gamer Nebula master Grey/Pink | F3: 6 | G3: 84.42 | H3: =G3/$E$11 -> 70.768715
C4: AGNEBULA-GRY-O | D4: 5600413205020 | E4: Alpha Gamer Nebula master Grey/Orange | F4: 13 | G4: 84.42 | H4: =G4/$E$11 -> 70.768715
C5: AGNYSA-BK | D5: 5600413205488 | E5: Alpha Gamer Nysa - Black | F5: 324 | G5: 67.39 | H5: =G5/$E$11 -> 56.492581
C6: AGNEBULA | D6: 5600413204054 | E6: Alpha Gamer Nebula master Grey/Black | F6: 50 | G6: 84.42 | H6: =G6/$E$11 -> 70.768715
H7: =G7/$E$11 -> 0
H8: =G8/$E$11 -> 0
H9: =G9/$E$11 -> 0
D11: Cambio | E11: 1.1929

Sheet SEKU7815288
C2: REFERENCIA | E2: PRODUTOS | F2: QUANT. | J2: INICIO
C3: OFFYLYMA | D3: 5600413206324 | E3: Offy Lyma - Cadeira de Escritório em Malha | F3: 85 | G3: 34.5 | H3: =G3/$E$11 -> 28.921117
C4: OFFYLYMAGREY | D4: 5600413207741 | E4: Offy Lyma Grey - Cadeira de Escritório em Malha | F4: 45 | G4: 37.5 | H4: =G4/$E$11 -> 31.435996
C5: AGLUNAGRY | D5: 5600413207758 | E5: Alpha Gamer Luna Grey - Cadeira em Malha | F5: 55 | G5: 80.5 | H5: =G5/$E$11 -> 67.482605
C6: AGAURORA | D6: 5600413206355 | E6: Alpha Gamer Aurora - Cadeira em Malha | F6: 105 | G6: 98 | H6: =G6/$E$11 -> 82.152737
C7: AGIRIS | D7: 5600413206362 | E7: Alpha Gamer Iris - Cadeira em Malha | F7: 45 | G7: 88 | H7: =G7/$E$11 -> 73.769805
C8: AGASTRID | D8: 5600413206416 | E8: Alpha Gamer Astrid - Cadeira em Malha | F8: 55 | G8: 145 | H8: =G8/$E$11 -> 121.55252
C9: AGSTELLA-BK | D9: 5600413206423 | E9: Alpha Gamer Stella Black - Cadeira em Malha | F9: 21 | G9: 60.5 | H9: =G9/$E$11 -> 50.716741
D11: Cambio | E11: 1.1929

Sheet SEKU7815267
C2: REFERENCIA | E2: PRODUTOS | F2: QUANT. | J2: INICIO
C3: AGSTELLA-BK | D3: 5600413206423 | E3: Alpha Gamer Stella Black - Cadeira em malha | F3: 175 | G3: 60.5 | H3: =G3/$E$10 -> 50.716741
C4: AGSTELLA-GRY | D4: 5600413206430 | E4: Alpha Gamer Stella Grey - Cadeira em malha | F4: 120 | G4: 65.5 | H4: =G4/$E$10 -> 54.908207
C5: AGSTELLA-WT-GRY | D5: 5600413206447 | E5: Alpha Gamer Stella White / Grey - Cadeira em malha | F5: 150 | G5: 65.5 | H5: =G5/$E$10 -> 54.908207
H6: =G6/$E$10 -> 0
H7: =G7/$E$10 -> 0
H8: =G8/$E$10 -> 0
D10: Cambio | E10: 1.1929

Sheet CMAU7126778
C2: REFERENCIA | E2: PRODUTOS | F2: QUANT. | J2: INICIO
C3: AGNEBULAOE-PU-BWN | D3: 5600413206379 | E3: Alpha Gamer Nebula Office Edition - PU Brown | F3: 357 | G3: 84.42 | H3: =G3/$E$10 -> 70.768715
H4: =G4/$E$10 -> 0
H5: =G5/$E$10 -> 0
H6: =G6/$E$10 -> 0
H7: =G7/$E$10 -> 0
H8: =G8/$E$10 -> 0
D10: Cambio | E10: 1.1929

Sheet MSMU5852428
C2: REFERENCIA | E2: PRODUTOS | F2: QUANT. | J2: INICIO
C3: OFFYLYMA | D3: 5600413206324 | E3: Offy Lyma - Cadeira de Escritório em Malha | F3: 274 | G3: 34.5 | H3: =G3/$E$10 -> 29.272018
C4: OFFYCYLA | D4: 5600413206317 | E4: Offy Cyla - Cadeira de Escritório em Malha | F4: 116 | G4: 40 | H4: =G4/$E$10 -> 33.938571
C5: OFFYLYCAWT | D5: 5600413206409 | E5: Offy Lyca White - Cadeira de Escritório em Malha | F5: 56 | G5: 63 | H5: =G5/$E$10 -> 53.45325
C6: OFFYLYCABK | D6: 5600413206386 | E6: Offy Lyca Black - Cadeira de Escritório em Malha | F6: 76 | G6: 58 | H6: =G6/$E$10 -> 49.210928
H7: =G7/$E$10 -> 0
H8: =G8/$E$10 -> 0
D10: Cambio | E10: 1.1786

Sheet FSCU8840228
C2: REFERENCIA | E2: PRODUTOS | F2: QUANT. | J2: INICIO
C3: AGWAVEBK | D3: 5600413207789 | E3: Alpha Gamer Wave Black | F3: 50 | G3: 109 | H3: =G3/$E$13 -> 92.482606
C4: AGWAVEBKGRY | D4: 5600413207796 | E4: Alpha Gamer Wave Black / Grey | F4: 20 | G4: 109 | H4: =G4/$E$13 -> 92.482606
C5: AGMISTBK | D5: 5600413207802 | E5: Alpha Gamer Mist Black | F5: 50 | G5: 136 | H5: =G5/$E$13 -> 115.39114
C6: AGMISTBKGRY | D6: 5600413207819 | E6: Alpha Gamer Mist Black / Grey | F6: 20 | G6: 136 | H6: =G6/$E$13 -> 115.39114
C7: AGTIDEBK | D7: 5600413207826 | E7: Alpha Gamer Tide Black | F7: 35 | G7: 162 | H7: =G7/$E$13 -> 137.45121
C8: AGTIDEGRY | D8: 5600413207833 | E8: Alpha Gamer Tide Grey | F8: 15 | G8: 169 | H8: =G8/$E$13 -> 143.39046
C9: AGSWELLBK | D9: 5600413207963 | E9: Alpha Gamer Swell Black | F9: 35 | G9: 136 | H9: =G9/$E$13 -> 115.39114
C10: AGSWELLGRY | D10: 5600413207970 | E10: Alpha Gamer Swell Grey | F10: 14 | G10: 142 | H10: =G10/$E$13 -> 120.48193
C11: AGSWELLWTGRY | D11: 5600413207987 | E11: Alpha Gamer Swell White / Grey | F11: 14 | G11: 142 | H11: =G11/$E$13 -> 120.48193
D13: Cambio | E13: 1.1786

Sheet TCNU2374129
C2: REFERENCIA | E2: PRODUTOS | F2: QUANT. | J2: INICIO
C3: OFFYLYMA | D3: 5600413206324 | E3: Offy Lyma - Cadeira de Escritório em Malha | F3: 274 | G3: 34.5 | H3: =G3/$E$10 -> 29.272018
C4: OFFYCYLA | D4: 5600413206317 | E4: Offy Cyla - Cadeira de Escritório em Malha | F4: 116 | G4: 40 | H4: =G4/$E$10 -> 33.938571
C5: OFFYLYCAWT | D5: 5600413206409 | E5: Offy Lyca White - Cadeira de Escritório em Malha | F5: 56 | G5: 63 | H5: =G5/$E$10 -> 53.45325
C6: OFFYLYCABK | D6: 5600413206386 | E6: Offy Lyca Black - Cadeira de Escritório em Malha | F6: 76 | G6: 58 | H6: =G6/$E$10 -> 49.210928
H7: =G7/$E$10 -> 0
H8: =G8/$E$10 -> 0
D10: Cambio | E10: 1.1786

Sheet TCNU1554912
C2: REFERENCIA | E2: PRODUTOS | F2: QUANT. | J2: INICIO
C3: AGSTELLA-WT-GRY | D3: 5600413206447 | E3: Alpha Gamer Stella White / Grey - Cadeira em Malha | F3: 74 | G3: 65.5 | H3: =G3/$E$12 -> 55.57441
C4: AGSTELLA-GRY | D4: 5600413206430 | E4: Alpha Gamer Stella Grey - Cadeira em Malha | F4: 53 | G4: 65.5 | H4: =G4/$E$12 -> 55.57441
C5: AGSTELLA-BK | D5: 5600413206423 | E5: Alpha Gamer Stella Black - Cadeira em Malha | F5: 93 | G5: 60.5 | H5: =G5/$E$12 -> 51.332089
C6: AGIRIS | D6: 5600413206362 | E6: Alpha Gamer Iris - Cadeira em Malha | F6: 64 | G6: 88 | H6: =G6/$E$12 -> 74.664857
C7: AGAURORA | D7: 5600413206355 | E7: Alpha Gamer Aurora - Cadeira em Malha | F7: 54 | G7: 98 | H7: =G7/$E$12 -> 83.149499
C8: AGASTRID | D8: 5600413206416 | E8: Alpha Gamer Astrid - Cadeira em Malha | F8: 44 | G8: 145 | H8: =G8/$E$12 -> 123.02732
H9: =G9/$E$12 -> 0
H10: =G10/$E$12 -> 0
D12: Cambio | E12: 1.1786

Sheet CAAU5904294
C2: REFERENCIA | E2: PRODUTOS | F2: QUANT. | J2: INICIO
C3: AGSTELLA-WT-GRY | D3: 5600413206447 | E3: Alpha Gamer Stella White / Grey - Cadeira em Malha | F3: 74 | G3: 65.5 | H3: =G3/$E$12 -> 55.621603
C4: AGSTELLA-GRY | D4: 5600413206430 | E4: Alpha Gamer Stella Grey - Cadeira em Malha | F4: 53 | G4: 65.5 | H4: =G4/$E$12 -> 55.621603
C5: AGSTELLA-BK | D5: 5600413206423 | E5: Alpha Gamer Stella Black - Cadeira em Malha | F5: 93 | G5: 60.5 | H5: =G5/$E$12 -> 51.375679
C6: AGIRIS | D6: 5600413206362 | E6: Alpha Gamer Iris - Cadeira em Malha | F6: 64 | G6: 88 | H6: =G6/$E$12 -> 74.728261
C7: AGAURORA | D7: 5600413206355 | E7: Alpha Gamer Aurora - Cadeira em Malha | F7: 54 | G7: 98 | H7: =G7/$E$12 -> 83.220109
C8: AGASTRID | D8: 5600413206416 | E8: Alpha Gamer Astrid - Cadeira em Malha | F8: 44 | G8: 145 | H8: =G8/$E$12 -> 123.13179
H9: =G9/$E$12 -> 0
H10: =G10/$E$12 -> 0
D12: Cambio | E12: 1.1776

Sheet MSMU4227658
C2: REFERENCIA | E2: PRODUTOS | F2: QUANT. | J2: INICIO
C3: AGNEBULA | D3: 5600413204054 | E3: Alpha Gamer Nebula | F3: 357 | G3: 84.42 | H3: =G3/$E$13 -> 71.688179
H4: =G4/$E$13 -> 0
H5: =G5/$E$13 -> 0
H6: =G6/$E$13 -> 0
H7: =G7/$E$13 -> 0
H8: =G8/$E$13 -> 0
H9: =G9/$E$13 -> 0
H10: =G10/$E$13 -> 0
H11: =G11/$E$13 -> 0
D13: Cambio | E13: 1.1776

Sheet MRSU7266658
A1: 1.1929
C2: REFERENCIA | E2: PRODUTOS | F2: QUANT. | J2: INICIO
C3: AGCYGNUS | D3: 5600413204191 | E3: Alpha Gamer Cygnus RGB | F3: 392 | G3: 71.64 | H3: =G3/$E$13 -> 60.055327
H4: =G4/$E$13 -> 0
H5: =G5/$E$13 -> 0
H6: =G6/$E$13 -> 0
H7: =G7/$E$13 -> 0
H8: =G8/$E$13 -> 0
H9: =G9/$E$13 -> 0
H10: =G10/$E$13 -> 0
H11: =G11/$E$13 -> 0
D13: Cambio | E13: 1.1929

Sheet MRKU4372041
C2: REFERENCIA | E2: PRODUTOS | F2: QUANT. | J2: INICIO
C3: AGGEMINARGBBK | D3: 5600413207321 | E3: Alpha Gamer Gemina RGB Black - Secretária Gaming | F3: 225 | G3: 38 | H3: =G3/$E$11 -> 32.744507
C4: AGGEMINABK | D4: 5600413207338 | E4: Alpha Gamer Gemina Black - Secretária Gaming | F4: 225 | G4: 27 | H4: =G4/$E$11 -> 23.265834
C5: AGSTARLARGBBK | D5: 5600413207345 | E5: Alpha Gamer Starla RGB Black - Secretária gaming | F5: 284 | G5: 71.5 | H5: =G5/$E$11 -> 61.611374
C6: AGZORYARGBBK | D6: 5600413207307 | E6: Alpha Gamer Zorya RGB Black - Secretaria Gaming Altura Regulável | F6: 124 | G6: 107 | H6: =G6/$E$11 -> 92.201637
H7: =G7/$E$11 -> 0
H8: =G8/$E$11 -> 0
H9: =G9/$E$11 -> 0
D11: Cambio | E11: 1.1605

Sheet TRHU4437683
C2: REFERENCIA | E2: PRODUTOS | F2: QUANT. | J2: INICIO
C3: AGIRIS | D3: 5600413206362 | E3: Alpha Gamer Iris - Cadeira em Malha | F3: 50 | G3: 88 | H3: =G3/$E$13 -> 73.769805
C4: AGASTRID | D4: 5600413206416 | E4: Alpha Gamer Astrid - Cadeira em Malha | F4: 100 | G4: 145 | H4: =G4/$E$13 -> 121.55252
C5: AGSTELLA-BK | D5: 5600413206423 | E5: Alpha Gamer Stella Black - Cadeira em Malha | F5: 85 | G5: 60.5 | H5: =G5/$E$13 -> 50.716741
C6: AGSTELLA-GRY | D6: 5600413206430 | E6: Alpha Gamer Stella Grey - Cadeira em Malha | F6: 70 | G6: 65.5 | H6: =G6/$E$13 -> 54.908207
C7: AGSTELLA-WT-GRY | D7: 5600413206447 | E7: Alpha Gamer Stella White / Grey - Cadeira em Malha | F7: 85 | G7: 65.5 | H7: =G7/$E$13 -> 54.908207
H8: =G8/$E$13 -> 0
H9: =G9/$E$13 -> 0
H10: =G10/$E$13 -> 0
H11: =G11/$E$13 -> 0
D13: Cambio | E13: 1.1929

Sheet TCNU5152906
C2: REFERENCIA | E2: PRODUTOS | F2: QUANT. | J2: INICIO
C3: ZLDCORE120PWMBK | D3: 5600413207628 | E3: Zolyd Core 120 mm PWM Fan Black | F3: 500 | G3: 1.9 | H3: =G3/$E$13 -> 1.618123
C4: ZLDHFLOWARGB240 | D4: 5600413208014 | E4: Zolyd Hyperflow ARGB 240 mm Liquid Cooling System | F4: 250 | G4: 26 | H4: =G4/$E$13 -> 22.142735
C5: ZLDHFLOWARGB360 | D5: 5600413208021 | E5: Zolyd Hyperflow ARGB 360 mm Liquid Cooling System | F5: 250 | G5: 32 | H5: =G5/$E$13 -> 27.252598
C6: ZLDNOCT | D6: 5600413208038 | E6: Zolyd Noct - Caixa PC ATX | F6: 300 | G6: 22.3 | H6: =G6/$E$13 -> 18.991654
C7: ZLDNODE | D7: 5600413208052 | E7: Zolyd Node - Caixa PC Micro-ATX + 500W 80 Plus Bronze PSU | F7: 500 | G7: 30.1 | H7: =G7/$E$13 -> 25.634475
C8: ZLDPULSAR | D8: 5600413208045 | E8: Zolyd Pulsar - Caixa PC Micro-ATX | F8: 274 | G8: 26.9 | H8: =G8/$E$13 -> 22.909215
H9: =G9/$E$13 -> 0
H10: =G10/$E$13 -> 0
H11: =G11/$E$13 -> 0
D13: Cambio | E13: 1.1742

Sheet HASU4497484
C2: REFERENCIA | E2: PRODUTOS | F2: QUANT. | J2: INICIO
C3: OFFYLYMAGREY | D3: 5600413207741 | E3: Offy Lyma Grey - Cadeira de Escritório em Malha | F3: 20 | G3: 37.5 | H3: =G3/$E$13 -> 31.435996
C4: AGLUNAV2 | D4: 5600413207390 | E4: Alpha Gamer Luna V2 - Cadeira em Malha | F4: 125 | G4: 71 | H4: =G4/$E$13 -> 59.51882
C5: AGLUNAGRY | D5: 5600413207758 | E5: Alpha Gamer Luna Grey - Cadeira em Malha | F5: 60 | G5: 80.5 | H5: =G5/$E$13 -> 67.482605
C6: AGAURORA | D6: 5600413206355 | E6: Alpha Gamer Aurora - Cadeira em Malha | F6: 150 | G6: 98 | H6: =G6/$E$13 -> 82.152737
C7: AGIRIS | D7: 5600413206362 | E7: Alpha Gamer Iris - Cadeira em Malha | F7: 30 | G7: 88 | H7: =G7/$E$13 -> 73.769805
H8: =G8/$E$13 -> 0
H9: =G9/$E$13 -> 0
H10: =G10/$E$13 -> 0
H11: =G11/$E$13 -> 0
D13: Cambio | E13: 1.1929

Sheet FANU3359264
C2: REFERENCIA | E2: PRODUTOS | F2: QUANT. | J2: INICIO
C3: NXHUMMERAEROWH | D3: 8436587975981 | E3: Nox Hummer Aero - ARGB Hyperflow Mid Tower - White | F3: 150 | G3: 35.81 | H3: =G3/$E$13 -> 30.690778
C4: NXHUMMERAEROBK | D4: 8436587975974 | E4: Nox Hummer Aero - ARGB Hyperflow Mid Tower - Black | F4: 170 | G4: 33 | H4: =G4/$E$13 -> 28.282482
C5: NXINFTYIOTAWH | D5: 8436587976018 | E5: Nox Infinity IOTA - ARGB Mesh Mid Tower - White | F5: 150 | G5: 27.5 | H5: =G5/$E$13 -> 23.568735
C6: NXINFTYIOTABK | D6: 8436587976001 | E6: Nox Infinity IOTA - ARGB Mesh Mid Tower - Black | F6: 170 | G6: 31.4 | H6: =G6/$E$13 -> 26.91121
C7: NXHUMMERSIGNALWH | D7: 8436587975967 | E7: Nox Hummer Signal - ARGB Frameless Mid Tower - White | F7: 150 | G7: 36.75 | H7: =G7/$E$13 -> 31.4964
C8: NXHUMMERSIGNALBK | D8: 8436587975950 | E8: Nox Hummer Signal - ARGB Frameless Mid Tower - Black | F8: 170 | G8: 34.13 | H8: =G8/$E$13 -> 29.250943
H9: =G9/$E$13 -> 0
H10: =G10/$E$13 -> 0
H11: =G11/$E$13 -> 0
D13: Cambio | E13: 1.1668

Sheet MRKU3567877
C2: REFERENCIA | E2: PRODUTOS | F2: QUANT. | J2: INICIO
C3: ZLDVYNTRIX | D3: 5600413206799 | E3: Zolyd Vyntrix - Tempered Glass ARGB M-ATX | F3: 131 | G3: 18.5 | H3: =G3/$E$13 -> 15.915348
C4: ZLDRIVEXAWT | D4: 5600413206874 | E4: Zolyd Rivexa White - ARGB Infinity Mirror ATX | F4: 300 | G4: 34.6 | H4: =G4/$E$13 -> 29.766001
C5: ZLDRIVEXABK | D5: 5600413206867 | E5: Zolyd Rivexa Black - ARGB Infinity Mirror ATX | F5: 213 | G5: 32 | H5: =G5/$E$13 -> 27.52925
C6: PCDIGABCM | D6: 5600413206119 | E6: PCDIGA Basic Chair Mat | F6: 500 | G6: 7.2 | H6: =G6/$E$13 -> 6.1940812
C7: PCDIGAMPBEBK | D7: 5600413204856 | E7: PCDIGA Mousepad Basic Extended - Black | F7: 5000 | G7: 1.95 | H7: =G7/$E$13 -> 1.6775637
H8: =G8/$E$13 -> 0
H9: =G9/$E$13 -> 0
H10: =G10/$E$13 -> 0
H11: =G11/$E$13 -> 0
D13: Cambio | E13: 1.1624

Sheet MSKU9770693
C2: REFERENCIA | E2: PRODUTOS | F2: QUANT. | J2: INICIO
C3: AGNEBULA | D3: 5600413204054 | E3: Alpha Gamer Nebula | F3: 357 | G3: 84.42 | H3: =G3/$E$13 -> 72.625602
H4: =G4/$E$13 -> 0
H5: =G5/$E$13 -> 0
H6: =G6/$E$13 -> 0
H7: =G7/$E$13 -> 0
H8: =G8/$E$13 -> 0
H9: =G9/$E$13 -> 0
H10: =G10/$E$13 -> 0
H11: =G11/$E$13 -> 0
D13: Cambio | E13: 1.1624

Sheet MRSU7112185
C2: REFERENCIA | E2: PRODUTOS | F2: QUANT. | J2: INICIO
C3: AGALEGRA-PUL-BK-V2 | D3: 5600413207062 | E3: Alpha Gamer Alegra - PU Leather Black V2 | F3: 80 | G3: 124.2 | H3: =G3/$E$13 -> 106.05414
C4: AGALEGRA-PUL-GRY-V2 | D4: 5600413207079 | E4: Alpha Gamer Alegra - PU Leather Grey / Black V2 | F4: 80 | G4: 124.2 | H4: =G4/$E$13 -> 106.05414
C5: AGALEGRA-PUL-WHT-V2 | D5: 5600413207086 | E5: Alpha Gamer Alegra - PU Leather White / Black V2 | F5: 20 | G5: 124.2 | H5: =G5/$E$13 -> 106.05414
C6: AGMAYA-BK | D6: 5600413205372 | E6: Alpha Gamer Maya - Black | F6: 156 | G6: 45.3 | H6: =G6/$E$13 -> 38.681581
H7: =G7/$E$13 -> 0
H8: =G8/$E$13 -> 0
H9: =G9/$E$13 -> 0
H10: =G10/$E$13 -> 0
H11: =G11/$E$13 -> 0
D13: Cambio | E13: 1.1711

Sheet CRD 24 11-2
